Workbook
Name UPDATE: 'Data Sheet'!$E$1

Sheet Profit & Loss
A1: ='Data Sheet'!B1 -> ASIAN PAINTS LTD | H1: =UPDATE | M1: SCREENER.IN
A3: Narration | B3: ='Data Sheet'!B16 -> 42825 | C3: ='Data Sheet'!C16 -> 43190 | D3: ='Data Sheet'!D16 -> 43555 | E3: ='Data Sheet'!E16 -> 43921 | F3: ='Data Sheet'!F16 -> 44286 | G3: ='Data Sheet'!G16 -> 44651 | H3: ='Data Sheet'!H16 -> 45016 | I3: ='Data Sheet'!I16 -> 45382 | ... K3: ='Data Sheet'!K16 -> 46112 | L3: Trailing | M3: Best Case | N3: Worst Case
A4: Sales | B4: ='Data Sheet'!B17 -> 15061.99 | C4: ='Data Sheet'!C17 -> 16824.55 | D4: ='Data Sheet'!D17 -> 19240.13 | E4: ='Data Sheet'!E17 -> 20211.25 | F4: ='Data Sheet'!F17 -> 21712.79 | G4: ='Data Sheet'!G17 -> 29101.28 | H4: ='Data Sheet'!H17 -> 34488.59 | I4: ='Data Sheet'!I17 -> 35494.73 | ... K4: ='Data Sheet'!K17 -> 35583.54 | L4: =SUM(Quarters!H4:K4) -> 37186.93 | M4: =$K4+M23*K4 -> 37344.497 | N4: =$K4+N23*L4 -> 35972.986
A5: Expenses | B5: =SUM('Data Sheet'!B18,'Data Sheet'!B20:B24, -1*'Data Sheet'!B19) -> 12068.23 | C5: =SUM('Data Sheet'!C18,'Data Sheet'!C20:C24, -1*'Data Sheet'!C19) -> 13620.54 | D5: =SUM('Data Sheet'!D18,'Data Sheet'!D20:D24, -1*'Data Sheet'!D19) -> 15475.19 | E5: =SUM('Data Sheet'!E18,'Data Sheet'!E20:E24, -1*'Data Sheet'!E19) -> 16049.48 | F5: =SUM('Data Sheet'!F18,'Data Sheet'!F20:F24, -1*'Data Sheet'!F19) -> 16857.19 | G5: =SUM('Data Sheet'!G18,'Data Sheet'!G20:G24, -1*'Data Sheet'!G19) -> 24297.67 | H5: =SUM('Data Sheet'!H18,'Data Sheet'!H20:H24, -1*'Data Sheet'!H19) -> 28228.75 | I5: =SUM('Data Sheet'!I18,'Data Sheet'!I20:I24, -1*'Data Sheet'!I19) -> 27909.75 | ... K5: =SUM('Data Sheet'!K18,'Data Sheet'!K20:K24, -1*'Data Sheet'!K19) -> 28883.81 | L5: =SUM(Quarters!H5:K5) -> 29947.22 | M5: =M4-M6 -> 30074.111 | N5: =N4-N6 -> 29282.085
A6: Operating Profit | B6: =B4-B5 -> 2993.76 | C6: =C4-C5 -> 3204.01 | D6: =D4-D5 -> 3764.94 | E6: =E4-E5 -> 4161.77 | F6: =F4-F5 -> 4855.6 | G6: =G4-G5 -> 4803.61 | H6: =H4-H5 -> 6259.84 | I6: =I4-I5 -> 7584.98 | ... K6: =K4-K5 -> 6699.73 | L6: =SUM(Quarters!H6:K6) -> 7239.71 | M6: =M4*M24 -> 7270.3858 | N6: =N4*N24 -> 6690.9009
A7: Other Income | B7: ='Data Sheet'!B25 -> 337.9 | C7: ='Data Sheet'!C25 -> 336.41 | D7: ='Data Sheet'!D25 -> 273.77 | E7: ='Data Sheet'!E25 -> 350.1 | F7: ='Data Sheet'!F25 -> 331.65 | G7: ='Data Sheet'!G25 -> 295.88 | H7: ='Data Sheet'!H25 -> 431.46 | I7: ='Data Sheet'!I25 -> 820.96 | ... K7: ='Data Sheet'!K25 -> 727.97 | L7: =SUM(Quarters!H7:K7) -> 781.68 | M7: 0 | N7: 0
A8: Depreciation | B8: ='Data Sheet'!B26 -> 334.79 | C8: ='Data Sheet'!C26 -> 360.47 | D8: ='Data Sheet'!D26 -> 622.14 | E8: ='Data Sheet'!E26 -> 780.5 | F8: ='Data Sheet'!F26 -> 791.27 | G8: ='Data Sheet'!G26 -> 816.36 | H8: ='Data Sheet'!H26 -> 858.02 | I8: ='Data Sheet'!I26 -> 853 | ... K8: ='Data Sheet'!K26 -> 1228.85 | L8: =SUM(Quarters!H8:K8) -> 1232.17 | M8: =+$L8 -> 1232.17 | N8: =+$L8 -> 1232.17
A9: Interest | B9: ='Data Sheet'!B27 -> 37.33 | C9: ='Data Sheet'!C27 -> 41.47 | D9: ='Data Sheet'!D27 -> 110.47 | E9: ='Data Sheet'!E27 -> 102.33 | F9: ='Data Sheet'!F27 -> 91.63 | G9: ='Data Sheet'!G27 -> 95.41 | H9: ='Data Sheet'!H27 -> 144.45 | I9: ='Data Sheet'!I27 -> 205.17 | ... K9: ='Data Sheet'!K27 -> 195.41 | L9: =SUM(Quarters!H9:K9) -> 198.74 | M9: =+$L9 -> 198.74 | N9: =+$L9 -> 198.74
A10: Profit before tax | B10: ='Data Sheet'!B28 -> 2959.54 | C10: ='Data Sheet'!C28 -> 3138.48 | D10: ='Data Sheet'!D28 -> 3306.1 | E10: ='Data Sheet'!E28 -> 3629.04 | F10: ='Data Sheet'!F28 -> 4304.35 | G10: ='Data Sheet'!G28 -> 4187.72 | H10: ='Data Sheet'!H28 -> 5688.83 | I10: ='Data Sheet'!I28 -> 7347.77 | ... K10: ='Data Sheet'!K28 -> 6003.44 | L10: =SUM(Quarters!H10:K10) -> 6590.48 | M10: =M6+M7-SUM(M8:M9) -> 5839.4758 | N10: =N6+N7-SUM(N8:N9) -> 5259.9909
A11: Tax | B11: ='Data Sheet'!B29 -> 943.29 | C11: ='Data Sheet'!C29 -> 1040.96 | D11: ='Data Sheet'!D29 -> 1098.06 | E11: ='Data Sheet'!E29 -> 854.85 | F11: ='Data Sheet'!F29 -> 1097.6 | G11: ='Data Sheet'!G29 -> 1102.91 | H11: ='Data Sheet'!H29 -> 1493.5 | I11: ='Data Sheet'!I29 -> 1790.08 | ... K11: ='Data Sheet'!K29 -> 1608.75 | L11: =SUM(Quarters!H11:K11) -> 1753.39 | M11: =IF($L10>0,$L11/$L10,0) -> 0.26604891 | N11: =IF($L10>0,$L11/$L10,0) -> 0.26604891
A12: Net profit | B12: ='Data Sheet'!B30 -> 1939.43 | C12: ='Data Sheet'!C30 -> 2038.93 | D12: ='Data Sheet'!D30 -> 2155.92 | E12: ='Data Sheet'!E30 -> 2705.17 | F12: ='Data Sheet'!F30 -> 3139.29 | G12: ='Data Sheet'!G30 -> 3030.57 | H12: ='Data Sheet'!H30 -> 4106.45 | I12: ='Data Sheet'!I30 -> 5460.23 | ... K12: ='Data Sheet'!K30 -> 4325.35 | L12: =SUM(Quarters!H12:K12) -> 4764.83 | M12: =M10-M11*M10 -> 4285.8896 | N12: =N10-N11*N10 -> 3860.5761
A13: EPS | B13: =IF('Data Sheet'!B93>0,B12/'Data Sheet'!B93,0) -> 20.219245 | C13: =IF('Data Sheet'!C93>0,C12/'Data Sheet'!C93,0) -> 21.256568 | D13: =IF('Data Sheet'!D93>0,D12/'Data Sheet'!D93,0) -> 22.47623 | E13: =IF('Data Sheet'!E93>0,E12/'Data Sheet'!E93,0) -> 28.202356 | F13: =IF('Data Sheet'!F93>0,F12/'Data Sheet'!F93,0) -> 32.728211 | G13: =IF('Data Sheet'!G93>0,G12/'Data Sheet'!G93,0) -> 31.594766 | H13: =IF('Data Sheet'!H93>0,H12/'Data Sheet'!H93,0) -> 42.811197 | I13: =IF('Data Sheet'!I93>0,I12/'Data Sheet'!I93,0) -> 56.924833 | ... K13: =IF('Data Sheet'!K93>0,K12/'Data Sheet'!K93,0) -> 45.093307 | L13: =IF('Data Sheet'!$B6>0,'Profit & Loss'!L12/'Data Sheet'!$B6,0) -> 49.675156 | M13: =IF('Data Sheet'!$B6>0,'Profit & Loss'!M12/'Data Sheet'!$B6,0) -> 44.682021 | N13: =IF('Data Sheet'!$B6>0,'Profit & Loss'!N12/'Data Sheet'!$B6,0) -> 40.247966
A14: Price to earning | B14: =IF(B15>0,B15/B13,"") -> 53.092981 | C14: =IF(C15>0,C15/C13,"") -> 52.708415 | D14: =IF(D15>0,D15/D13,"") -> 66.412383 | E14: =IF(E15>0,E15/E13,"") -> 59.090808 | F14: =IF(F15>0,F15/F13,"") -> 77.529444 | G14: =IF(G15>0,G15/G13,"") -> 97.482917 | H14: =IF(H15>0,H15/H13,"") -> 64.507657 | I14: =IF(I15>0,I15/I13,"") -> 50.00893 | ... K14: =IF(K15>0,K15/K13,"") -> 48.015995 | L14: =IF(L13>0,L15/L13,0) -> 48.454805 | M14: =M25 -> 51.925432 | N14: =N25 -> 48.454805
A15: Price | B15: ='Data Sheet'!B90 -> 1073.5 | C15: ='Data Sheet'!C90 -> 1120.4 | D15: ='Data Sheet'!D90 -> 1492.7 | E15: ='Data Sheet'!E90 -> 1666.5 | F15: ='Data Sheet'!F90 -> 2537.4 | G15: ='Data Sheet'!G90 -> 3079.95 | H15: ='Data Sheet'!H90 -> 2761.65 | I15: ='Data Sheet'!I90 -> 2846.75 | ... K15: ='Data Sheet'!K90 -> 2165.2 | L15: ='Data Sheet'!B8 -> 2407 | M15: =M13*M14 -> 2320.1333 | N15: =N13*N14 -> 1950.2074
A17: RATIOS:
A18: Dividend Payout | B18: =IF('Data Sheet'!B30>0, 'Data Sheet'!B31/'Data Sheet'!B30, 0) -> 0.50941772 | C18: =IF('Data Sheet'!C30>0, 'Data Sheet'!C31/'Data Sheet'!C30, 0) -> 0.4092833 | D18: =IF('Data Sheet'!D30>0, 'Data Sheet'!D31/'Data Sheet'!D30, 0) -> 0.46716019 | E18: =IF('Data Sheet'!E30>0, 'Data Sheet'!E31/'Data Sheet'!E30, 0) -> 0.42549636 | F18: =IF('Data Sheet'!F30>0, 'Data Sheet'!F31/'Data Sheet'!F30, 0) -> 0.54540039 | G18: =IF('Data Sheet'!G30>0, 'Data Sheet'!G31/'Data Sheet'!G30, 0) -> 0.6061137 | H18: =IF('Data Sheet'!H30>0, 'Data Sheet'!H31/'Data Sheet'!H30, 0) -> 0.59914281 | I18: =IF('Data Sheet'!I30>0, 'Data Sheet'!I31/'Data Sheet'!I30, 0) -> 0.58498268 | ... K18: =IF('Data Sheet'!K30>0, 'Data Sheet'!K31/'Data Sheet'!K30, 0) -> 0.6098466
A19: OPM | B19: =IF(B6>0,B6/B4,0) -> 0.19876258 | C19: =IF(C6>0,C6/C4,0) -> 0.19043659 | D19: =IF(D6>0,D6/D4,0) -> 0.19568163 | E19: =IF(E6>0,E6/E4,0) -> 0.20591354 | F19: =IF(F6>0,F6/F4,0) -> 0.22362856 | G19: =IF(G6>0,G6/G4,0) -> 0.16506525 | H19: =IF(H6>0,H6/H4,0) -> 0.18150467 | I19: =IF(I6>0,I6/I4,0) -> 0.21369313 | ... L19: =IF(L6>0,L6/L4,0) -> 0.19468426
G22: TRENDS: | H22: 10 YEARS | I22: 7 YEARS | J22: 5 YEARS | K22: 3 YEARS | L22: RECENT | M22: BEST | N22: WORST
G23: Sales Growth | H23: =IF(B4=0,"",POWER($K4/B4,1/9)-1) -> 0.10023435 | I23: =IF(D4=0,"",POWER($K4/D4,1/7)-1) -> 0.091814193 | J23: =IF(F4=0,"",POWER($K4/F4,1/5)-1) -> 0.10384146 | K23: =IF(H4=0,"",POWER($K4/H4, 1/3)-1) -> 0.010472667 | L23: =IF(ISERROR(MAX(IF(J4=0,"",(K4-J4)/J4),IF(K4=0,"",(L4-K4)/K4))),"",MAX(IF(J4=0,"",(K4-J4)/J4),IF(K4=0,"",(L4-K4)/K4))) -> 0.049487961 | M23: =MAX(K23:L23) -> 0.049487961 | N23: =MIN(H23:L23) -> 0.010472667
G24: OPM | H24: =IF(SUM(B4:$K$4)=0,"",SUMPRODUCT(B19:$K$19,B4:$K$4)/SUM(B4:$K$4)) -> 0.19239198 | I24: =IF(SUM(E4:$K$4)=0,"",SUMPRODUCT(E19:$K$19,E4:$K$4)/SUM(E4:$K$4)) -> 0.19179174 | J24: =IF(SUM(G4:$K$4)=0,"",SUMPRODUCT(G19:$K$19,G4:$K$4)/SUM(G4:$K$4)) -> 0.18599793 | K24: =IF(SUM(I4:$K$4)=0, "", SUMPRODUCT(I19:$K$19,I4:$K$4)/SUM(I4:$K$4)) -> 0.19327651 | L24: =L19 -> 0.19468426 | M24: =MAX(K24:L24) -> 0.19468426 | N24: =MIN(H24:L24) -> 0.18599793
G25: Price to Earning | H25: =IF(ISERROR(AVERAGEIF(B14:$L14,">0")),"",AVERAGEIF(B14:$L14,">0")) -> 61.684212 | I25: =IF(ISERROR(AVERAGEIF(E14:$L14,">0")),"",AVERAGEIF(E14:$L14,">0")) -> 63.289069 | J25: =IF(ISERROR(AVERAGEIF(G14:$L14,">0")),"",AVERAGEIF(G14:$L14,">0")) -> 61.615384 | K25: =IF(ISERROR(AVERAGEIF(I14:$L14,">0")),"",AVERAGEIF(I14:$L14,">0")) -> 51.925432 | L25: =L14 -> 48.454805 | M25: =MAX(K25:L25) -> 51.925432 | N25: =MIN(H25:L25) -> 48.454805

Sheet Quarters
A1: ='Profit & Loss'!A1 -> ASIAN PAINTS LTD | E1: =UPDATE | J1: SCREENER.IN
A3: Narration | B3: ='Data Sheet'!B41 -> 45382 | C3: ='Data Sheet'!C41 -> 45473 | D3: ='Data Sheet'!D41 -> 45565 | E3: ='Data Sheet'!E41 -> 45657 | F3: ='Data Sheet'!F41 -> 45747 | G3: ='Data Sheet'!G41 -> 45838 | H3: ='Data Sheet'!H41 -> 45930 | I3: ='Data Sheet'!I41 -> 46022 | ... K3: ='Data Sheet'!K41 -> 46203
A4: Sales | B4: ='Data Sheet'!B42 -> 8730.76 | C4: ='Data Sheet'!C42 -> 8969.73 | D4: ='Data Sheet'!D42 -> 8027.54 | E4: ='Data Sheet'!E42 -> 8549.44 | F4: ='Data Sheet'!F42 -> 8358.91 | G4: ='Data Sheet'!G42 -> 8938.55 | H4: ='Data Sheet'!H42 -> 8531.27 | I4: ='Data Sheet'!I42 -> 8867.02 | ... K4: ='Data Sheet'!K42 -> 10541.94
A5: Expenses | B5: ='Data Sheet'!B43 -> 7039.39 | C5: ='Data Sheet'!C43 -> 7275.96 | D5: ='Data Sheet'!D43 -> 6788.03 | E5: ='Data Sheet'!E43 -> 6912.71 | F5: ='Data Sheet'!F43 -> 6922.71 | G5: ='Data Sheet'!G43 -> 7313.58 | H5: ='Data Sheet'!H43 -> 7027.89 | I5: ='Data Sheet'!I43 -> 7086.06 | ... K5: ='Data Sheet'!K43 -> 8373.18
A6: Operating Profit | B6: ='Data Sheet'!B50 -> 1691.37 | C6: ='Data Sheet'!C50 -> 1693.77 | D6: ='Data Sheet'!D50 -> 1239.51 | E6: ='Data Sheet'!E50 -> 1636.73 | F6: ='Data Sheet'!F50 -> 1436.2 | G6: ='Data Sheet'!G50 -> 1624.97 | H6: ='Data Sheet'!H50 -> 1503.38 | I6: ='Data Sheet'!I50 -> 1780.96 | ... K6: ='Data Sheet'!K50 -> 2168.76
A7: Other Income | B7: ='Data Sheet'!B44 -> 212.43 | C7: ='Data Sheet'!C44 -> 192.93 | D7: ='Data Sheet'!D44 -> 24.53 | E7: ='Data Sheet'!E44 -> 192.82 | F7: ='Data Sheet'!F44 -> -60.06 | G7: ='Data Sheet'!G44 -> 229.11 | H7: ='Data Sheet'!H44 -> 236.94 | I7: ='Data Sheet'!I44 -> 69.14 | ... K7: ='Data Sheet'!K44 -> 279.01
A8: Depreciation | B8: ='Data Sheet'!B45 -> 225.61 | C8: ='Data Sheet'!C45 -> 227.7 | D8: ='Data Sheet'!D45 -> 241.99 | E8: ='Data Sheet'!E45 -> 255.55 | F8: ='Data Sheet'!F45 -> 301.1 | G8: ='Data Sheet'!G45 -> 300.87 | H8: ='Data Sheet'!H45 -> 304.93 | I8: ='Data Sheet'!I45 -> 313.07 | ... K8: ='Data Sheet'!K45 -> 304.19
A9: Interest | B9: ='Data Sheet'!B46 -> 54.1 | C9: ='Data Sheet'!C46 -> 55.38 | D9: ='Data Sheet'!D46 -> 63.01 | E9: ='Data Sheet'!E46 -> 55.84 | F9: ='Data Sheet'!F46 -> 52.79 | G9: ='Data Sheet'!G46 -> 44.5 | H9: ='Data Sheet'!H46 -> 43.87 | I9: ='Data Sheet'!I46 -> 47.94 | ... K9: ='Data Sheet'!K46 -> 47.83
A10: Profit before tax | B10: ='Data Sheet'!B47 -> 1624.09 | C10: ='Data Sheet'!C47 -> 1603.62 | D10: ='Data Sheet'!D47 -> 959.04 | E10: ='Data Sheet'!E47 -> 1518.16 | F10: ='Data Sheet'!F47 -> 1022.25 | G10: ='Data Sheet'!G47 -> 1508.71 | H10: ='Data Sheet'!H47 -> 1391.52 | I10: ='Data Sheet'!I47 -> 1489.09 | ... K10: ='Data Sheet'!K47 -> 2095.75
A11: Tax | B11: ='Data Sheet'!B48 -> 348.79 | C11: ='Data Sheet'!C48 -> 416.83 | D11: ='Data Sheet'!D48 -> 265.38 | E11: ='Data Sheet'!E48 -> 389.73 | F11: ='Data Sheet'!F48 -> 321.42 | G11: ='Data Sheet'!G48 -> 391.66 | H11: ='Data Sheet'!H48 -> 373.29 | I11: ='Data Sheet'!I48 -> 415.17 | ... K11: ='Data Sheet'!K48 -> 536.3
A12: Net profit | B12: ='Data Sheet'!B49 -> 1256.72 | C12: ='Data Sheet'!C49 -> 1169.98 | D12: ='Data Sheet'!D49 -> 694.64 | E12: ='Data Sheet'!E49 -> 1110.48 | F12: ='Data Sheet'!F49 -> 692.13 | G12: ='Data Sheet'!G49 -> 1099.77 | H12: ='Data Sheet'!H49 -> 993.59 | I12: ='Data Sheet'!I49 -> 1059.87 | ... K12: ='Data Sheet'!K49 -> 1539.25
A14: OPM | B14: =IF(B4>0,B6/B4,"") -> 0.1937254 | C14: =IF(C4>0,C6/C4,"") -> 0.18883177 | D14: =IF(D4>0,D6/D4,"") -> 0.1544072 | E14: =IF(E4>0,E6/E4,"") -> 0.19144295 | F14: =IF(F4>0,F6/F4,"") -> 0.17181666 | G14: =IF(G4>0,G6/G4,"") -> 0.18179347 | H14: =IF(H4>0,H6/H4,"") -> 0.17621995 | I14: =IF(I4>0,I6/I4,"") -> 0.20085215 | ... K14: =IF(K4>0,K6/K4,"") -> 0.20572684

Sheet Balance Sheet
A1: ='Profit & Loss'!A1 -> ASIAN PAINTS LTD | E1: =UPDATE | J1: SCREENER.IN
A3: Narration | B3: ='Data Sheet'!B56 -> 42825 | C3: ='Data Sheet'!C56 -> 43190 | D3: ='Data Sheet'!D56 -> 43555 | E3: ='Data Sheet'!E56 -> 43921 | F3: ='Data Sheet'!F56 -> 44286 | G3: ='Data Sheet'!G56 -> 44651 | H3: ='Data Sheet'!H56 -> 45016 | I3: ='Data Sheet'!I56 -> 45382 | ... K3: ='Data Sheet'!K56 -> 46112
A4: Equity Share Capital | B4: ='Data Sheet'!B57 -> 95.92 | C4: ='Data Sheet'!C57 -> 95.92 | D4: ='Data Sheet'!D57 -> 95.92 | E4: ='Data Sheet'!E57 -> 95.92 | F4: ='Data Sheet'!F57 -> 95.92 | G4: ='Data Sheet'!G57 -> 95.92 | H4: ='Data Sheet'!H57 -> 95.92 | I4: ='Data Sheet'!I57 -> 95.92 | ... K4: ='Data Sheet'!K57 -> 95.92
A5: Reserves | B5: ='Data Sheet'!B58 -> 7507.97 | C5: ='Data Sheet'!C58 -> 8314.31 | D5: ='Data Sheet'!D58 -> 9374.63 | E5: ='Data Sheet'!E58 -> 10034.24 | F5: ='Data Sheet'!F58 -> 12710.37 | G5: ='Data Sheet'!G58 -> 13715.64 | H5: ='Data Sheet'!H58 -> 15896.31 | I5: ='Data Sheet'!I58 -> 18632.38 | ... K5: ='Data Sheet'!K58 -> 21275.67
A6: Borrowings | B6: ='Data Sheet'!B59 -> 560.34 | C6: ='Data Sheet'!C59 -> 533.43 | D6: ='Data Sheet'!D59 -> 1319.6 | E6: ='Data Sheet'!E59 -> 1118.5 | F6: ='Data Sheet'!F59 -> 1093.12 | G6: ='Data Sheet'!G59 -> 1586.88 | H6: ='Data Sheet'!H59 -> 1932.62 | I6: ='Data Sheet'!I59 -> 2474.38 | ... K6: ='Data Sheet'!K59 -> 3928.93
A7: Other Liabilities | B7: ='Data Sheet'!B60 -> 4240.96 | C7: ='Data Sheet'!C60 -> 4819.82 | D7: ='Data Sheet'!D60 -> 5458.69 | E7: ='Data Sheet'!E60 -> 4889.31 | F7: ='Data Sheet'!F60 -> 6455.93 | G7: ='Data Sheet'!G60 -> 7559.99 | H7: ='Data Sheet'!H60 -> 7854.48 | I7: ='Data Sheet'!I60 -> 8698.09 | ... K7: ='Data Sheet'!K60 -> 9218.23
A8: Total | B8: ='Data Sheet'!B61 -> 12405.19 | C8: ='Data Sheet'!C61 -> 13763.48 | D8: ='Data Sheet'!D61 -> 16248.84 | E8: ='Data Sheet'!E61 -> 16137.97 | F8: ='Data Sheet'!F61 -> 20355.34 | G8: ='Data Sheet'!G61 -> 22958.43 | H8: ='Data Sheet'!H61 -> 25779.33 | I8: ='Data Sheet'!I61 -> 29900.77 | ... K8: ='Data Sheet'!K61 -> 34518.75
A10: Net Block | B10: ='Data Sheet'!B62 -> 3303.74 | C10: ='Data Sheet'!C62 -> 3732.24 | D10: ='Data Sheet'!D62 -> 6496.56 | E10: ='Data Sheet'!E62 -> 6272.31 | F10: ='Data Sheet'!F62 -> 5858.52 | G10: ='Data Sheet'!G62 -> 5519.06 | H10: ='Data Sheet'!H62 -> 5770.46 | I10: ='Data Sheet'!I62 -> 7146.62 | ... K10: ='Data Sheet'!K62 -> 9640.28
A11: Capital Work in Progress | B11: ='Data Sheet'!B63 -> 257.54 | C11: ='Data Sheet'!C63 -> 1405.11 | D11: ='Data Sheet'!D63 -> 209.67 | E11: ='Data Sheet'!E63 -> 140.24 | F11: ='Data Sheet'!F63 -> 182.98 | G11: ='Data Sheet'!G63 -> 426.43 | H11: ='Data Sheet'!H63 -> 1019.59 | I11: ='Data Sheet'!I63 -> 2698.37 | ... K11: ='Data Sheet'!K63 -> 1848.67
A12: Investments | B12: ='Data Sheet'!B64 -> 2651.99 | C12: ='Data Sheet'!C64 -> 2140.7 | D12: ='Data Sheet'!D64 -> 2568.58 | E12: ='Data Sheet'!E64 -> 2018.85 | F12: ='Data Sheet'!F64 -> 4736.8 | G12: ='Data Sheet'!G64 -> 3247.53 | H12: ='Data Sheet'!H64 -> 4261.71 | I12: ='Data Sheet'!I64 -> 4587.92 | ... K12: ='Data Sheet'!K64 -> 7061.74
A13: Other Assets | B13: ='Data Sheet'!B65 -> 6191.92 | C13: ='Data Sheet'!C65 -> 6485.43 | D13: ='Data Sheet'!D65 -> 6974.03 | E13: ='Data Sheet'!E65 -> 7706.57 | F13: ='Data Sheet'!F65 -> 9577.04 | G13: ='Data Sheet'!G65 -> 13765.41 | H13: ='Data Sheet'!H65 -> 14727.57 | I13: ='Data Sheet'!I65 -> 15467.86 | ... K13: ='Data Sheet'!K65 -> 15968.06
A14: Total | B14: ='Data Sheet'!B66 -> 12405.19 | C14: ='Data Sheet'!C66 -> 13763.48 | D14: ='Data Sheet'!D66 -> 16248.84 | E14: ='Data Sheet'!E66 -> 16137.97 | F14: ='Data Sheet'!F66 -> 20355.34 | G14: ='Data Sheet'!G66 -> 22958.43 | H14: ='Data Sheet'!H66 -> 25779.33 | I14: ='Data Sheet'!I66 -> 29900.77 | ... K14: ='Data Sheet'!K66 -> 34518.75
A16: Working Capital | B16: =B13-B7 -> 1950.96 | C16: =C13-C7 -> 1665.61 | D16: =D13-D7 -> 1515.34 | E16: =E13-E7 -> 2817.26 | F16: =F13-F7 -> 3121.11 | G16: =G13-G7 -> 6205.42 | H16: =H13-H7 -> 6873.09 | I16: =I13-I7 -> 6769.77 | ... K16: =K13-K7 -> 6749.83
A17: Debtors | B17: ='Data Sheet'!B67 -> 1446.6 | C17: ='Data Sheet'!C67 -> 1730.63 | D17: ='Data Sheet'!D67 -> 1907.33 | E17: ='Data Sheet'!E67 -> 1795.22 | F17: ='Data Sheet'!F67 -> 2602.17 | G17: ='Data Sheet'!G67 -> 3871.44 | H17: ='Data Sheet'!H67 -> 4636.94 | I17: ='Data Sheet'!I67 -> 4889.05 | ... K17: ='Data Sheet'!K67 -> 4461.8
A18: Inventory | B18: ='Data Sheet'!B68 -> 2626.94 | C18: ='Data Sheet'!C68 -> 2658.31 | D18: ='Data Sheet'!D68 -> 3149.86 | E18: ='Data Sheet'!E68 -> 3389.81 | F18: ='Data Sheet'!F68 -> 3798.6 | G18: ='Data Sheet'!G68 -> 6152.98 | H18: ='Data Sheet'!H68 -> 6210.64 | I18: ='Data Sheet'!I68 -> 5923.41 | ... K18: ='Data Sheet'!K68 -> 5743.69
A20: Debtor Days | B20: =IF('Profit & Loss'!B4>0,'Balance Sheet'!B17/('Profit & Loss'!B4/365),0) -> 35.055726 | C20: =IF('Profit & Loss'!C4>0,'Balance Sheet'!C17/('Profit & Loss'!C4/365),0) -> 37.545132 | D20: =IF('Profit & Loss'!D4>0,'Balance Sheet'!D17/('Profit & Loss'!D4/365),0) -> 36.183511 | E20: =IF('Profit & Loss'!E4>0,'Balance Sheet'!E17/('Profit & Loss'!E4/365),0) -> 32.420325 | F20: =IF('Profit & Loss'!F4>0,'Balance Sheet'!F17/('Profit & Loss'!F4/365),0) -> 43.743436 | G20: =IF('Profit & Loss'!G4>0,'Balance Sheet'!G17/('Profit & Loss'!G4/365),0) -> 48.557163 | H20: =IF('Profit & Loss'!H4>0,'Balance Sheet'!H17/('Profit & Loss'!H4/365),0) -> 49.073711 | I20: =IF('Profit & Loss'!I4>0,'Balance Sheet'!I17/('Profit & Loss'!I4/365),0) -> 50.275161 | ... K20: =IF('Profit & Loss'!K4>0,'Balance Sheet'!K17/('Profit & Loss'!K4/365),0) -> 45.767144
A21: Inventory Turnover | B21: =IF('Balance Sheet'!B18>0,'Profit & Loss'!B4/'Balance Sheet'!B18,0) -> 5.7336635 | C21: =IF('Balance Sheet'!C18>0,'Profit & Loss'!C4/'Balance Sheet'!C18,0) -> 6.3290399 | D21: =IF('Balance Sheet'!D18>0,'Profit & Loss'!D4/'Balance Sheet'!D18,0) -> 6.1082493 | E21: =IF('Balance Sheet'!E18>0,'Profit & Loss'!E4/'Balance Sheet'!E18,0) -> 5.9623548 | F21: =IF('Balance Sheet'!F18>0,'Profit & Loss'!F4/'Balance Sheet'!F18,0) -> 5.715998 | G21: =IF('Balance Sheet'!G18>0,'Profit & Loss'!G4/'Balance Sheet'!G18,0) -> 4.7296237 | H21: =IF('Balance Sheet'!H18>0,'Profit & Loss'!H4/'Balance Sheet'!H18,0) -> 5.5531459 | I21: =IF('Balance Sheet'!I18>0,'Profit & Loss'!I4/'Balance Sheet'!I18,0) -> 5.9922798 | ... K21: =IF('Balance Sheet'!K18>0,'Profit & Loss'!K4/'Balance Sheet'!K18,0) -> 6.1952403
A23: Return on Equity | B23: =IF(SUM('Balance Sheet'!B4:B5)>0,'Profit & Loss'!B12/SUM('Balance Sheet'!B4:B5),"") -> 0.25505761 | C23: =IF(SUM('Balance Sheet'!C4:C5)>0,'Profit & Loss'!C12/SUM('Balance Sheet'!C4:C5),"") -> 0.24243451 | D23: =IF(SUM('Balance Sheet'!D4:D5)>0,'Profit & Loss'!D12/SUM('Balance Sheet'!D4:D5),"") -> 0.22764465 | E23: =IF(SUM('Balance Sheet'!E4:E5)>0,'Profit & Loss'!E12/SUM('Balance Sheet'!E4:E5),"") -> 0.26704119 | F23: =IF(SUM('Balance Sheet'!F4:F5)>0,'Profit & Loss'!F12/SUM('Balance Sheet'!F4:F5),"") -> 0.24513657 | G23: =IF(SUM('Balance Sheet'!G4:G5)>0,'Profit & Loss'!G12/SUM('Balance Sheet'!G4:G5),"") -> 0.21942272 | H23: =IF(SUM('Balance Sheet'!H4:H5)>0,'Profit & Loss'!H12/SUM('Balance Sheet'!H4:H5),"") -> 0.25677782 | I23: =IF(SUM('Balance Sheet'!I4:I5)>0,'Profit & Loss'!I12/SUM('Balance Sheet'!I4:I5),"") -> 0.29154969 | ... K23: =IF(SUM('Balance Sheet'!K4:K5)>0,'Profit & Loss'!K12/SUM('Balance Sheet'!K4:K5),"") -> 0.20238784
A24: Return on Capital Emp | C24: =IF((B4+B5+B6+C4+C5+C6)>0,('Profit & Loss'!C10+'Profit & Loss'!C9)*2/(B4+B5+B6+C4+C5+C6),"") -> 0.37175245 | D24: =IF((C4+C5+C6+D4+D5+D6)>0,('Profit & Loss'!D10+'Profit & Loss'!D9)*2/(C4+C5+C6+D4+D5+D6),"") -> 0.34626562 | E24: =IF((D4+D5+D6+E4+E5+E6)>0,('Profit & Loss'!E10+'Profit & Loss'!E9)*2/(D4+D5+D6+E4+E5+E6),"") -> 0.3386181 | F24: =IF((E4+E5+E6+F4+F5+F6)>0,('Profit & Loss'!F10+'Profit & Loss'!F9)*2/(E4+E5+E6+F4+F5+F6),"") -> 0.34960774 | G24: =IF((F4+F5+F6+G4+G5+G6)>0,('Profit & Loss'!G10+'Profit & Loss'!G9)*2/(F4+F5+F6+G4+G5+G6),"") -> 0.29238528 | H24: =IF((G4+G5+G6+H4+H5+H6)>0,('Profit & Loss'!H10+'Profit & Loss'!H9)*2/(G4+G5+G6+H4+H5+H6),"") -> 0.35010229 | I24: =IF((H4+H5+H6+I4+I5+I6)>0,('Profit & Loss'!I10+'Profit & Loss'!I9)*2/(H4+H5+H6+I4+I5+I6),"") -> 0.38606781 | J24: =IF((I4+I5+I6+J4+J5+J6)>0,('Profit & Loss'!J10+'Profit & Loss'!J9)*2/(I4+I5+I6+J4+J5+J6),"") -> 0.24853087 | K24: =IF((J4+J5+J6+K4+K5+K6)>0,('Profit & Loss'!K10+'Profit & Loss'!K9)*2/(J4+J5+J6+K4+K5+K6),"") -> 0.26383351

Sheet Analysis
A1: ASIAN PAINTS ANALYSIS (₹ CRORE )
A3: ITEMS | B3: Mar-24 | C3: Mar-25 | D3: Mar-26
A4: SALES | B4: 35494.73 | C4: 33905.62 | D4: 35583.54
A5: OPERATING PROFIT | B5: 7584.98 | C5: 6006.21 | D5: 6699.73
A6: NET PROFIT | B6: 5460.23 | C6: 3667.23 | D6: 4325.35
A7: INTEREST | B7: 205.17 | C7: 227.02 | D7: 195.41
A9: RATIOS
A10: OPERATING MARGIN | B10: =B5/B4 -> 0.21369313 | C10: =C5/C4 -> 0.17714497 | D10: =D5/D4 -> 0.18828172
A11: NET PROFIT MARGIN | B11: =B6/B4 -> 0.15383213 | C11: =C6/C4 -> 0.10815995 | D11: =D6/D4 -> 0.1215548
A12: SALES GROWTH | C12: =(C4-B4)/B4 -> -0.044770308 | D12: =(D4-C4)/C4 -> 0.049487961
A14: FROM BALANCE SHEET
A15: BORROWINGS | B15: 2474.38 | C15: 2290.29 | D15: 3928.93
A16: EQUITY SHARE CAPITAL | B16: 95.92 | C16: 95.92 | D16: 95.92
A17: RESERVES | B17: 18632.38 | C17: 19303.89 | D17: 21275.67
A18: TOTAL EQUITY | B18: =B16+B17 -> 18728.3 | C18: =C16+C17 -> 19399.81 | D18: =D16+D17 -> 21371.59
A19: TOTAL ASSET | B19: 29900.77 | C19: 30355.25 | D19: 34518.75
A21: MORE RATIOS
A22: RETURN ON EQUITY | B22: =B6/B18 -> 0.29154969 | C22: =C6/C18 -> 0.18903433 | D22: =D6/D18 -> 0.20238784
A23: NET PROFIT GROWTH | C23: =(C6-B6)/B6 -> -0.32837445 | D23: =(D6-C6)/C6 -> 0.1794597
A24: RETURN ON ASSET % | B24: =B6/B19*100 -> 18.261169 | C24: =C6/C19*100 -> 12.08104 | D24: =D6/D19*100 -> 12.530436
A25: ASSET TURNOVER | B25: =B4/B19 -> 1.1870841 | C25: =C4/C19 -> 1.1169607 | D25: =D4/D19 -> 1.0308467
A26: INTEREST COVERAGE | B26: =B5/B7 -> 36.969245 | C26: =C5/C7 -> 26.456744 | D26: =D5/D7 -> 34.285502
A27: DEBT- TO- EQUITY | B27: =B15/B18 -> 0.13211984 | C27: =C15/C18 -> 0.11805734 | D27: =D15/D18 -> 0.18383892
A29: ANALYSIS: WHAT THE NUMBERS SHOW (MAR-24 TO MAR-26)
A30: 1. SALES: Sales fell 4.48% in Mar-25 (35,495 to 33,906 crore), then grew 4.95% in Mar-26 to 35,584 crore.
A31: 2. MARGINS: Operating margin fell from 21.37% to 17.71% in Mar-25 and recovered to 18.83% in Mar-26. Net profit margin moved 15.38%, 10.82%, 12.16%.
A32: 3. PROFIT: Net profit dropped from 5,460 to 3,667 crore in Mar-25 and rose to 4,325 crore in Mar-26, still below Mar-24.
A33: 4. DEBT: Debt-to-equity is low (0.13, 0.12, 0.18). Borrowings rose from 2,290 to 3,929 crore in Mar-26, so debt is increasing.
A34: 5. RETURN: ROE fell from 29.15% to 18.90% and recovered to 20.24%. Mar-24 was the best year.
A35: 6. ASSETS: Return on assets fell from 18.26% to 12.08%. Asset turnover fell from 1.19 t 1.03.
A36: 7. SAFETY: Interest coverage ratio is high (36.97, 26.46,34.29), so profit easily pays the interest.
A37: CONCLUSION: Asian Paints is a low-debt, profitable company. Mar-25 was weak, Mar-26 shows recovery but has not reached Mar-24 levels.
A38: TO CHECK NEXT: Why did Mar-25 sales and margins fall? Read the annual report for the reason.

Sheet Cash Flow
A1: ='Balance Sheet'!A1 -> ASIAN PAINTS LTD | E1: =UPDATE | J1: SCREENER.IN
A3: Narration | B3: ='Data Sheet'!B81 -> 42825 | C3: ='Data Sheet'!C81 -> 43190 | D3: ='Data Sheet'!D81 -> 43555 | E3: ='Data Sheet'!E81 -> 43921 | F3: ='Data Sheet'!F81 -> 44286 | G3: ='Data Sheet'!G81 -> 44651 | H3: ='Data Sheet'!H81 -> 45016 | I3: ='Data Sheet'!I81 -> 45382 | ... K3: ='Data Sheet'!K81 -> 46112
A4: Cash from Operating Activity | B4: ='Data Sheet'!B82 -> 1527.33 | C4: ='Data Sheet'!C82 -> 2113.44 | D4: ='Data Sheet'!D82 -> 2469.54 | E4: ='Data Sheet'!E82 -> 3038.15 | F4: ='Data Sheet'!F82 -> 3683.35 | G4: ='Data Sheet'!G82 -> 986.49 | H4: ='Data Sheet'!H82 -> 4193.43 | I4: ='Data Sheet'!I82 -> 6103.6 | ... K4: ='Data Sheet'!K82 -> 7088.18
A5: Cash from Investing Activity | B5: ='Data Sheet'!B83 -> -681.11 | C5: ='Data Sheet'!C83 -> -1556.14 | D5: ='Data Sheet'!D83 -> -917.79 | E5: ='Data Sheet'!E83 -> -517.91 | F5: ='Data Sheet'!F83 -> -540.54 | G5: ='Data Sheet'!G83 -> -316.75 | H5: ='Data Sheet'!H83 -> -1282.34 | I5: ='Data Sheet'!I83 -> -2548.48 | ... K5: ='Data Sheet'!K83 -> -1328.23
A6: Cash from Financing Activity | B6: ='Data Sheet'!B84 -> -756.43 | C6: ='Data Sheet'!C84 -> -1379.14 | D6: ='Data Sheet'!D84 -> -1117.46 | E6: ='Data Sheet'!E84 -> -2871.46 | F6: ='Data Sheet'!F84 -> -650.4 | G6: ='Data Sheet'!G84 -> -1807.61 | H6: ='Data Sheet'!H84 -> -2140.05 | I6: ='Data Sheet'!I84 -> -2982.5 | ... K6: ='Data Sheet'!K84 -> -2376.51
A7: Net Cash Flow | B7: ='Data Sheet'!B85 -> 89.79 | C7: ='Data Sheet'!C85 -> -821.84 | D7: ='Data Sheet'!D85 -> 434.29 | E7: ='Data Sheet'!E85 -> -351.22 | F7: ='Data Sheet'!F85 -> 2492.41 | G7: ='Data Sheet'!G85 -> -1137.87 | H7: ='Data Sheet'!H85 -> 771.04 | I7: ='Data Sheet'!I85 -> 572.62 | ... K7: ='Data Sheet'!K85 -> 3383.44

Sheet Data Sheet
A1: COMPANY NAME | B1: ASIAN PAINTS LTD | E1: =IF(B2<>B3, "A NEW VERSION OF THE WORKSHEET IS AVAILABLE", "")
A2: LATEST VERSION | B2: 2.1 | E2: PLEASE DO NOT MAKE ANY CHANGES TO THIS SHEET
A3: CURRENT VERSION | B3: 2.1
A5: META
A6: Number of shares | B6: =IF(B9>0, B9/B8, 0) -> 95.91978
A7: Face Value | B7: 1
A8: Current Price | B8: 2407
A9: Market Capitalization | B9: 230878.91
A15: PROFIT & LOSS
A16: Report Date | B16: 42825 | C16: 43190 | D16: 43555 | E16: 43921 | F16: 44286 | G16: 44651 | H16: 45016 | I16: 45382 | J16: 45747 | K16: 46112
A17: Sales | B17: 15061.99 | C17: 16824.55 | D17: 19240.13 | E17: 20211.25 | F17: 21712.79 | G17: 29101.28 | H17: 34488.59 | I17: 35494.73 | J17: 33905.62 | K17: 35583.54
A18: Raw Material Cost | B18: 7452.6 | C18: 8128.17 | D18: 9974.4 | E18: 9981.99 | F18: 10425.55 | G18: 17123.25 | H18: 18985.53 | I18: 17410.84 | J18: 17504.51 | K18: 17142.01
A19: Change in Inventory | B19: 528.6 | C19: -142.13 | D19: 293.26 | E19: 239.15 | F19: 92.45 | G19: 1324.97 | H19: 309.73 | I19: -363.8 | J19: 205 | K19: -603.68
A20: Power and Fuel | B20: 106.02 | C20: 110.3 | D20: 119.63 | E20: 97.79 | F20: 86.05 | G20: 117.23 | H20: 138.29 | I20: 133.25 | J20: 148.58 | K20: 167.1
A21: Other Mfr. Exp | B21: 1662.75 | C21: 1691.68 | D21: 1862.35 | E21: 1946.12 | F21: 2068.31 | G21: 2880.45 | H21: 2916.2 | I21: 2767.18 | J21: 2687.4 | K21: 2767.11
A22: Employee Cost | B22: 1039.89 | C22: 1121.89 | D22: 1242.69 | E22: 1371.27 | F22: 1547.61 | G22: 1794.61 | H22: 2036.41 | I22: 2334.92 | J22: 2605.78 | K22: 2809.73
A23: Selling and admin | B23: 4364.04 | C23: 2254.92 | D23: 2366.87 | E23: 2311.51 | F23: 2245.69 | G23: 2941.98 | H23: 3500.84 | I23: 3811.86 | J23: 3874.94 | K23: 4112.07
A24: Other Expenses | B24: -2028.47 | C24: 171.45 | D24: 202.51 | E24: 579.95 | F24: 576.43 | G24: 765.12 | H24: 961.21 | I24: 1087.9 | J24: 1283.2 | K24: 1282.11
A25: Other Income | B25: 337.9 | C25: 336.41 | D25: 273.77 | E25: 350.1 | F25: 331.65 | G25: 295.88 | H25: 431.46 | I25: 820.96 | J25: 350.22 | K25: 727.97
A26: Depreciation | B26: 334.79 | C26: 360.47 | D26: 622.14 | E26: 780.5 | F26: 791.27 | G26: 816.36 | H26: 858.02 | I26: 853 | J26: 1026.34 | K26: 1228.85
A27: Interest | B27: 37.33 | C27: 41.47 | D27: 110.47 | E27: 102.33 | F27: 91.63 | G27: 95.41 | H27: 144.45 | I27: 205.17 | J27: 227.02 | K27: 195.41
... A31: Dividend Amount | B31: 987.98 | C31: 834.5 | D31: 1007.16 | E31: 1151.04 | F31: 1712.17 | G31: 1836.87 | H31: 2460.35 | I31: 3194.14 | J31: 2378.82 | K31: 2637.8
A40: Quarters
A41: Report Date | B41: 45382 | C41: 45473 | D41: 45565 | E41: 45657 | F41: 45747 | G41: 45838 | H41: 45930 | I41: 46022 | J41: 46112 | K41: 46203
A42: Sales | B42: 8730.76 | C42: 8969.73 | D42: 8027.54 | E42: 8549.44 | F42: 8358.91 | G42: 8938.55 | H42: 8531.27 | I42: 8867.02 | J42: 9246.7 | K42: 10541.94
A43: Expenses | B43: 7039.39 | C43: 7275.96 | D43: 6788.03 | E43: 6912.71 | F43: 6922.71 | G43: 7313.58 | H43: 7027.89 | I43: 7086.06 | J43: 7460.09 | K43: 8373.18
A44: Other Income | B44: 212.43 | C44: 192.93 | D44: 24.53 | E44: 192.82 | F44: -60.06 | G44: 229.11 | H44: 236.94 | I44: 69.14 | J44: 196.59 | K44: 279.01
A45: Depreciation | B45: 225.61 | C45: 227.7 | D45: 241.99 | E45: 255.55 | F45: 301.1 | G45: 300.87 | H45: 304.93 | I45: 313.07 | J45: 309.98 | K45: 304.19
A46: Interest | B46: 54.1 | C46: 55.38 | D46: 63.01 | E46: 55.84 | F46: 52.79 | G46: 44.5 | H46: 43.87 | I46: 47.94 | J46: 59.1 | K46: 47.83
A47: Profit before tax | B47: 1624.09 | C47: 1603.62 | D47: 959.04 | E47: 1518.16 | F47: 1022.25 | G47: 1508.71 | H47: 1391.52 | I47: 1489.09 | J47: 1614.12 | K47: 2095.75
A48: Tax | B48: 348.79 | C48: 416.83 | D48: 265.38 | E48: 389.73 | F48: 321.42 | G48: 391.66 | H48: 373.29 | I48: 415.17 | J48: 428.63 | K48: 536.3
A49: Net profit | B49: 1256.72 | C49: 1169.98 | D49: 694.64 | E49: 1110.48 | F49: 692.13 | G49: 1099.77 | H49: 993.59 | I49: 1059.87 | J49: 1172.12 | K49: 1539.25
A50: Operating Profit | B50: 1691.37 | C50: 1693.77 | D50: 1239.51 | E50: 1636.73 | F50: 1436.2 | G50: 1624.97 | H50: 1503.38 | I50: 1780.96 | J50: 1786.61 | K50: 2168.76
A55: BALANCE SHEET
A56: Report Date | B56: 42825 | C56: 43190 | D56: 43555 | E56: 43921 | F56: 44286 | G56: 44651 | H56: 45016 | I56: 45382 | J56: 45747 | K56: 46112
A57: Equity Share Capital | B57: 95.92 | C57: 95.92 | D57: 95.92 | E57: 95.92 | F57: 95.92 | G57: 95.92 | H57: 95.92 | I57: 95.92 | J57: 95.92 | K57: 95.92
A58: Reserves | B58: 7507.97 | C58: 8314.31 | D58: 9374.63 | E58: 10034.24 | F58: 12710.37 | G58: 13715.64 | H58: 15896.31 | I58: 18632.38 | J58: 19303.89 | K58: 21275.67
A59: Borrowings | B59: 560.34 | C59: 533.43 | D59: 1319.6 | E59: 1118.5 | F59: 1093.12 | G59: 1586.88 | H59: 1932.62 | I59: 2474.38 | J59: 2290.29 | K59: 3928.93
A60: Other Liabilities | B60: 4240.96 | C60: 4819.82 | D60: 5458.69 | E60: 4889.31 | F60: 6455.93 | G60: 7559.99 | H60: 7854.48 | I60: 8698.09 | J60: 8665.15 | K60: 9218.23
A61: Total | B61: 12405.19 | C61: 13763.48 | D61: 16248.84 | E61: 16137.97 | F61: 20355.34 | G61: 22958.43 | H61: 25779.33 | I61: 29900.77 | J61: 30355.25 | K61: 34518.75
...
